Traceback (most recent call last):
  File "/home/steven/anaconda3/lib/python3.8/site-packages/jupyter_cache/executors/utils.py", line 51, in single_nb_execution
    executenb(
  File "/home/steven/anaconda3/lib/python3.8/site-packages/nbclient/client.py", line 1087, in execute
    return NotebookClient(nb=nb, resources=resources, km=km, **kwargs).execute()
  File "/home/steven/anaconda3/lib/python3.8/site-packages/nbclient/util.py", line 74, in wrapped
    return just_run(coro(*args, **kwargs))
  File "/home/steven/anaconda3/lib/python3.8/site-packages/nbclient/util.py", line 53, in just_run
    return loop.run_until_complete(coro)
  File "/home/steven/anaconda3/lib/python3.8/asyncio/base_events.py", line 616, in run_until_complete
    return future.result()
  File "/home/steven/anaconda3/lib/python3.8/site-packages/nbclient/client.py", line 540, in async_execute
    await self.async_execute_cell(
  File "/home/steven/anaconda3/lib/python3.8/site-packages/nbclient/client.py", line 832, in async_execute_cell
    self._check_raise_for_error(cell, exec_reply)
  File "/home/steven/anaconda3/lib/python3.8/site-packages/nbclient/client.py", line 740, in _check_raise_for_error
    raise CellExecutionError.from_cell_and_msg(cell, exec_reply['content'])
nbclient.exceptions.CellExecutionError: An error occurred while executing the following cell:
------------------
# find the best fit equation
slope, intercept, rval, pval, stderr = st.linregress(concurrent_df['Regional_Q'], concurrent_df['Project_Q'])
------------------

[0;31m---------------------------------------------------------------------------[0m
[0;31mValueError[0m                                Traceback (most recent call last)
[0;32m<ipython-input-17-1bbb1379dabc>[0m in [0;36m<module>[0;34m[0m
[1;32m      1[0m [0;31m# find the best fit equation[0m[0;34m[0m[0;34m[0m[0;34m[0m[0m
[0;32m----> 2[0;31m [0mslope[0m[0;34m,[0m [0mintercept[0m[0;34m,[0m [0mrval[0m[0;34m,[0m [0mpval[0m[0;34m,[0m [0mstderr[0m [0;34m=[0m [0mst[0m[0;34m.[0m[0mlinregress[0m[0;34m([0m[0mconcurrent_df[0m[0;34m[[0m[0;34m'Regional_Q'[0m[0;34m][0m[0;34m,[0m [0mconcurrent_df[0m[0;34m[[0m[0;34m'Project_Q'[0m[0;34m][0m[0;34m)[0m[0;34m[0m[0;34m[0m[0m
[0m
[0;32m~/anaconda3/lib/python3.8/site-packages/scipy/stats/_stats_mstats_common.py[0m in [0;36mlinregress[0;34m(x, y)[0m
[1;32m    107[0m [0;34m[0m[0m
[1;32m    108[0m     [0;32mif[0m [0mx[0m[0;34m.[0m[0msize[0m [0;34m==[0m [0;36m0[0m [0;32mor[0m [0my[0m[0;34m.[0m[0msize[0m [0;34m==[0m [0;36m0[0m[0;34m:[0m[0;34m[0m[0;34m[0m[0m
[0;32m--> 109[0;31m         [0;32mraise[0m [0mValueError[0m[0;34m([0m[0;34m"Inputs must not be empty."[0m[0;34m)[0m[0;34m[0m[0;34m[0m[0m
[0m[1;32m    110[0m [0;34m[0m[0m
[1;32m    111[0m     [0mn[0m [0;34m=[0m [0mlen[0m[0;34m([0m[0mx[0m[0;34m)[0m[0;34m[0m[0;34m[0m[0m

[0;31mValueError[0m: Inputs must not be empty.
ValueError: Inputs must not be empty.

